<?xml version="1.0"?>
<robot name="allien_diff_bot">
  <link name="base_footprint"/>

  <joint name="base_joint" type="fixed">
    <parent link="base_footprint"/>
    <child link="base_link" />
    <origin xyz="0 0 0" rpy="0 0 0"/>
  </joint>
  <link name="base_link">
    <visual>
      <geometry>
        <cylinder length="0.08" radius="0.2"/>
      </geometry>
      <material name="silver">
        <color rgba="0.75 0.75 0.75 1"/>
      </material>
    </visual>
    <collision>
      <geometry>
        <cylinder length="0.08" radius="0.155"/>
      </geometry>
    </collision>
    <inertial>
      <mass value="1.0"/>
      <inertia ixx="0.015" iyy="0.0375" izz="0.0375" ixy="0" ixz="0" iyz="0"/>
    </inertial>
  </link>
  <link name="caster">
    <visual>
      <geometry>
        <cylinder length="0.08" radius="0.05"/>
      </geometry>
      <material name="silver"/>
    </visual>
    <collision>
      <geometry>
        <cylinder length="0.08" radius="0.05"/>
      </geometry>
    </collision>
    <inertial>
      <mass value="0.1"/>
      <inertia ixx="0.00083" iyy="0.00083" izz="0.000167" ixy="0" ixz="0" iyz="0"/>
    </inertial>
  </link>

  <joint name="caster_joint" type="continuous">
    <axis xyz="0 0 1"/>
    <parent link="base_link"/>
    <child link="caster"/>
    <origin rpy="0 0 0" xyz="0.15 0 0"/>
  </joint>

  <link name="front_wheel">
    <visual>
      <geometry>
        <cylinder length="0.05" radius="0.035"/>
      </geometry>
      <material name="black"/>
    </visual>
    <collision>
      <geometry>
        <cylinder length="0.05" radius="0.035"/>
      </geometry>
    </collision>
    <inertial>
      <mass value="0.1"/>
      <inertia ixx="5.1458e-5" iyy="5.1458e-5" izz="6.125e-5" ixy="0" ixz="0" iyz="0"/>
    </inertial>
  </link>

  <joint name="front_wheel_joint" type="continuous">
    <axis xyz="0 0 1"/>
    <parent link="caster"/>
    <child link="front_wheel"/>
    <origin rpy="-1.5708 0 0" xyz="0.05 0 -.05"/>
  </joint>
  <link name="back_caster">
    <visual>
      <geometry>
        <cylinder length="0.08" radius="0.05"/>
      </geometry>
      <material name="silver"/>
    </visual>
    <collision>
      <geometry>
        <cylinder length="0.08" radius="0.05"/>
      </geometry>
    </collision>
    <inertial>
      <mass value="0.1"/>
      <inertia ixx="0.00083" iyy="0.00083" izz="0.000167" ixy="0" ixz="0" iyz="0"/>
    </inertial>
  </link>

  <joint name="back_caster_joint" type="continuous">
    <axis xyz="0 0 1"/>
    <parent link="base_link"/>
    <child link="back_caster"/>
    <origin rpy="0 0 0" xyz="-0.15 0 0"/>
  </joint>

  <link name="back_wheel">
    <visual>
      <geometry>
        <cylinder length="0.05" radius="0.035"/>
      </geometry>
      <material name="black"/>
    </visual>
    <collision>
      <geometry>
        <cylinder length="0.05" radius="0.035"/>
      </geometry>
    </collision>
    <inertial>
      <mass value="0.1"/>
      <inertia ixx="5.1458e-5" iyy="5.1458e-5" izz="6.125e-5" ixy="0" ixz="0" iyz="0"/>
    </inertial>
  </link>

  <joint name="back_wheel_joint" type="continuous">
    <axis xyz="0 0 1"/>
    <parent link="back_caster"/>
    <child link="back_wheel"/>
    <origin rpy="-1.5708 0 0" xyz="0.05 0 -.05"/>
  </joint>
  <link name="right_wheel">
    <visual>
      <geometry>
        <cylinder length="0.05" radius="0.035"/>
      </geometry>
      <material name="black">
        <color rgba="0 0 0 1"/>
      </material>
    </visual>
    <collision>
      <geometry>
        <cylinder length="0.05" radius="0.035"/>
      </geometry>
    </collision>
    <inertial>
      <mass value="0.1"/>
      <inertia ixx="5.1458e-5" iyy="5.1458e-5" izz="6.125e-5" ixy="0" ixz="0" iyz="0"/>
    </inertial>
  </link>

  <joint name="right_wheel_joint" type="continuous">
    <axis xyz="0 0 1"/>
    <parent link="base_link"/>
    <child link="right_wheel"/>
    <origin rpy="-1.5708 0 0" xyz="0 -0.16 -.05"/>
  </joint>

  <link name="left_wheel">
    <visual>
      <geometry>
        <cylinder length="0.05" radius="0.035"/>
      </geometry>
      <material name="black"/>
    </visual>
    <collision>
      <geometry>
        <cylinder length="0.05" radius="0.035"/>
      </geometry>
    </collision>
    <inertial>
      <mass value="0.1"/>
      <inertia ixx="5.1458e-5" iyy="5.1458e-5" izz="6.125e-5" ixy="0" ixz="0" iyz="0"/>
    </inertial>
  </link>

  <joint name="left_wheel_joint" type="continuous">
    <axis xyz="0 0 1"/>
    <parent link="base_link"/>
    <child link="left_wheel"/>
    <origin rpy="-1.5708 0 0" xyz="0 0.16 -.05"/>
  </joint>
  <link name="middle_link">
    <visual>
      <geometry>
        <cylinder length="0.3" radius="0.15"/>
      </geometry>
      <material name="silver">
        <color rgba="0.75 0.75 0.75 1"/>
      </material>
    </visual>
    <collision>
      <geometry>
        <cylinder length="0.3" radius="0.15"/>
      </geometry>
    </collision>
    <inertial>
      <mass value="1.0"/>
      <inertia ixx="0.015" iyy="0.0375" izz="0.0375" ixy="0" ixz="0" iyz="0"/>
    </inertial>
  </link>
  <joint name="middle_joint" type="fixed">
    <axis xyz="0 0 1"/>
    <parent link="base_link"/>
    <child link="middle_link"/>
    <origin rpy="0 0 0" xyz="0 0 0.15"/>
  </joint>
  <link name="top_link">
    <visual>
      <geometry>
        <sphere radius="0.15"/>
      </geometry>
      <material name="silver"/>
    </visual>
    <collision>
      <geometry>
        <sphere radius="0.15"/>
      </geometry>
      <material name="silver"/>
    </collision> 
    <inertial>
      <mass value="0.1"/>
      <inertia ixx="0.00083" iyy="0.00083" izz="0.000167" ixy="0" ixz="0" iyz="0"/>
    </inertial>
  </link>

  <joint name="top_joint" type="fixed">
    <axis xyz="0 0 1"/>
    <parent link="middle_link"/>
    <child link="top_link"/>
    <origin rpy="0 0 0" xyz="0 0 0.15"/>
  </joint>
  <link name="neck_link">
    <visual>
      <geometry>
        <cylinder length="0.05" radius="0.05"/>
      </geometry>
      <material name="silver"/>
    </visual>
    <collision>
      <geometry>
        <cylinder length="0.05" radius="0.05"/>
      </geometry>
      <material name="silver"/>
    </collision>
    <inertial>
      <mass value="0.1"/>
      <inertia ixx="0.00083" iyy="0.00083" izz="0.000167" ixy="0" ixz="0" iyz="0"/>
    </inertial>
  </link>

  <joint name="neck_joint" type="fixed">
    <axis xyz="0 0 1"/>
    <parent link="top_link"/>
    <child link="neck_link"/>
    <origin rpy="0 0 0" xyz="0 0 0.175"/>
    <limit effort="30" velocity="1.0" lower="-0.7" upper="0.7" />
  </joint>
  <link name="face_link">
    <visual>
      <geometry>
        <box size="0.125 0.275 0.125"/>
      </geometry>
      <material name="silver"/>
    </visual>
    <collision>
      <geometry>
        <box size="0.125 0.275 0.125"/>
      </geometry>
      <material name="silver"/>
    </collision>
    <inertial>
      <mass value="0.1"/>
      <inertia ixx="0.00083" iyy="0.00083" izz="0.000167" ixy="0" ixz="0" iyz="0"/>
    </inertial>
  </link>

  <joint name="face_joint" type="fixed">
    <axis xyz="0 0 1"/>
    <parent link="neck_link"/>
    <child link="face_link"/>
    <origin rpy="0 0 0" xyz="0 0 0.08"/>
  </joint>
  <link name="eye_link">
    <visual>
      <geometry>
        <box size="0.03 0.23  0.06"/>
      </geometry>
      <material name="black"/>
    </visual>
    <collision>
      <geometry>
        <box size="0.03 0.23 0.06"/>

      </geometry>
    </collision>
    <inertial>
      <mass value="0.1"/>
      <inertia ixx="0.00083" iyy="0.00083" izz="0.000167" ixy="0" ixz="0" iyz="0"/>
    </inertial>
  </link>
  <joint name="eye_joint" type="fixed">
    <axis xyz="0 0 1"/>
    <parent link="face_link"/>
    <child link="eye_link"/>
    <origin rpy="0 0 0" xyz="0.07 0 0.02"/>
  </joint>
  <link name="antennae_link">
    <visual>
      <geometry>
        <cylinder length="0.05" radius="0.01"/>
      </geometry>
      <material name="black"/>
    </visual>
    <collision>
      <geometry>
        <cylinder length="0.05" radius="0.01"/>
      </geometry>
      <material name="black"/>
    </collision>
    <inertial>
      <mass value="0.1"/>
      <inertia ixx="0.00083" iyy="0.00083" izz="0.000167" ixy="0" ixz="0" iyz="0"/>
    </inertial>
  </link>
  <joint name="antennae_joint" type="fixed">
    <axis xyz="0 0 1"/>
    <parent link="face_link"/>
    <child link="antennae_link"/>
    <origin rpy="0 0 0" xyz="0 0 0.08"/>
  </joint>
  <link name="laser_link">
    <visual>
      <geometry>
        <sphere radius="0.02"/>
      </geometry>
      <material name="black"/>
    </visual>
    <collision>
      <geometry>
        <sphere radius="0.02"/>
      </geometry>
      <material name="black"/>
    </collision>
    <inertial>
      <mass value="0.1"/>
      <inertia ixx="0.00083" iyy="0.00083" izz="0.000167" ixy="0" ixz="0" iyz="0"/>
    </inertial> 
  </link>
  <joint name="laser_joint" type="fixed">
    <axis xyz="0 0 1"/>
    <parent link="antennae_link"/>
    <child link="laser_link"/>
    <origin rpy="0 0 0" xyz="0 0 0.025"/>
  </joint>
  <gazebo reference="base_link">
     <material>Gazebo/Silver</material>
  </gazebo>
  <gazebo reference="middle_link">
     <material>Gazebo/Silver</material>
  </gazebo>
  <gazebo reference="top_link">
     <material>Gazebo/Silver</material>
  </gazebo>
  <gazebo reference="neck_link">
     <material>Gazebo/Silver</material>
  </gazebo>
  <gazebo reference="face_link">
     <material>Gazebo/Silver</material>
  </gazebo>
  <gazebo reference="castor">
     <material>Gazebo/Silver</material>
  </gazebo>
  <gazebo reference="back_castor">
     <material>Gazebo/Silver</material>
  </gazebo>
  <gazebo reference="front_wheel">
     <material>Gazebo/Silver</material>
  </gazebo>
  <gazebo reference="back_wheel">
     <material>Gazebo/Silver</material>
  </gazebo>
  <gazebo reference="left_wheel">
     <material>Gazebo/Black</material>
  </gazebo>
  <gazebo reference="right_wheel">
     <material>Gazebo/Black</material>
  </gazebo>
  <gazebo reference="eye_link">
     <material>Gazebo/Black</material>
  </gazebo>
  <gazebo reference="antennae_link">
     <material>Gazebo/Black</material>
  </gazebo>
  <gazebo reference="sphere_link">
     <material>Gazebo/Black</material>
  </gazebo>
</robot>
